Watching for file changes with StatReloader
Using the latest cached version of the dataset since mrheinen/linux-commands couldn't be found on the Hugging Face Hub
Found the latest cached dataset configuration 'default' at /home/paul/.cache/huggingface/datasets/mrheinen___linux-commands/default/0.0.0/c8d7587daf50b371f00838bb12549193a6abf5e5 (last modified on Tue Feb 11 13:57:43 2025).
[13/Feb/2025 14:32:22] "GET /api/system_status/ HTTP/1.1" 200 5334
[13/Feb/2025 14:32:22] "GET /static/rest_framework/css/bootstrap.min.css HTTP/1.1" 304 0
[13/Feb/2025 14:32:22] "GET /static/rest_framework/css/bootstrap-tweaks.css HTTP/1.1" 304 0
[13/Feb/2025 14:32:22] "GET /static/rest_framework/js/csrf.js HTTP/1.1" 304 0
[13/Feb/2025 14:32:22] "GET /static/rest_framework/css/default.css HTTP/1.1" 304 0
[13/Feb/2025 14:32:22] "GET /static/rest_framework/js/ajax-form.js HTTP/1.1" 304 0
[13/Feb/2025 14:32:22] "GET /static/rest_framework/css/prettify.css HTTP/1.1" 304 0
[13/Feb/2025 14:32:22] "GET /static/rest_framework/js/jquery-3.7.1.min.js HTTP/1.1" 304 0
[13/Feb/2025 14:32:22] "GET /static/rest_framework/js/bootstrap.min.js HTTP/1.1" 304 0
[13/Feb/2025 14:32:22] "GET /static/rest_framework/js/load-ajax-form.js HTTP/1.1" 304 0
[13/Feb/2025 14:32:22] "GET /static/rest_framework/js/prettify-min.js HTTP/1.1" 304 0
[13/Feb/2025 14:32:22] "GET /static/rest_framework/js/default.js HTTP/1.1" 304 0
[13/Feb/2025 14:32:22] "GET /static/rest_framework/js/ajax-form.js HTTP/1.1" 304 0
[13/Feb/2025 14:32:22] "GET /static/rest_framework/js/csrf.js HTTP/1.1" 304 0
[13/Feb/2025 14:32:22] "GET /static/rest_framework/js/jquery-3.7.1.min.js HTTP/1.1" 304 0
[13/Feb/2025 14:32:22] "GET /static/rest_framework/js/bootstrap.min.js HTTP/1.1" 304 0
[13/Feb/2025 14:32:22] "GET /static/rest_framework/js/default.js HTTP/1.1" 304 0
[13/Feb/2025 14:32:22] "GET /static/rest_framework/js/load-ajax-form.js HTTP/1.1" 304 0
[13/Feb/2025 14:32:22] "GET /static/rest_framework/js/prettify-min.js HTTP/1.1" 304 0
[13/Feb/2025 14:32:22] "GET /static/rest_framework/img/grid.png HTTP/1.1" 304 0
Not Found: /favicon.ico
[13/Feb/2025 14:32:22] "GET /favicon.ico HTTP/1.1" 404 2363
Method Not Allowed: /api/chat/
[13/Feb/2025 14:32:31] "GET /api/chat/ HTTP/1.1" 405 5571
[13/Feb/2025 14:32:52] "POST /api/chat/ HTTP/1.1" 200 5968
[13/Feb/2025 14:44:27] "POST /api/chat/ HTTP/1.1" 200 5899
/home/paul/project-ai/NeuroSys-AI/ai_config/ai_config/settings.py changed, reloading.
Performing system checks...

System check identified no issues (0 silenced).

You have 18 unapplied migration(s). Your project may not work properly until you apply the migrations for app(s): admin, auth, contenttypes, sessions.
Run 'python manage.py migrate' to apply them.
February 13, 2025 - 14:32:21
Django version 5.1.6, using settings 'ai_config.settings'
Starting development server at http://0.0.0.0:8080/
Quit the server with CONTROL-C.

Watching for file changes with StatReloader
Exception in thread django-main-thread:
Traceback (most recent call last):
  File "/home/paul/.local/share/virtualenvs/NeuroSys-AI-hMYEmNG9/lib/python3.12/site-packages/django/db/backends/postgresql/base.py", line 25, in <module>
    import psycopg as Database
ModuleNotFoundError: No module named 'psycopg'

During handling of the above exception, another exception occurred:

Traceback (most recent call last):
  File "/home/paul/.local/share/virtualenvs/NeuroSys-AI-hMYEmNG9/lib/python3.12/site-packages/django/db/backends/postgresql/base.py", line 27, in <module>
    import psycopg2 as Database
ModuleNotFoundError: No module named 'psycopg2'

During handling of the above exception, another exception occurred:

Traceback (most recent call last):
  File "/usr/lib/python3.12/threading.py", line 1073, in _bootstrap_inner
    self.run()
  File "/usr/lib/python3.12/threading.py", line 1010, in run
    self._target(*self._args, **self._kwargs)
  File "/home/paul/.local/share/virtualenvs/NeuroSys-AI-hMYEmNG9/lib/python3.12/site-packages/django/utils/autoreload.py", line 64, in wrapper
    fn(*args, **kwargs)
  File "/home/paul/.local/share/virtualenvs/NeuroSys-AI-hMYEmNG9/lib/python3.12/site-packages/django/core/management/commands/runserver.py", line 126, in inner_run
    autoreload.raise_last_exception()
  File "/home/paul/.local/share/virtualenvs/NeuroSys-AI-hMYEmNG9/lib/python3.12/site-packages/django/utils/autoreload.py", line 87, in raise_last_exception
    raise _exception[1]
  File "/home/paul/.local/share/virtualenvs/NeuroSys-AI-hMYEmNG9/lib/python3.12/site-packages/django/core/management/__init__.py", line 394, in execute
    autoreload.check_errors(django.setup)()
  File "/home/paul/.local/share/virtualenvs/NeuroSys-AI-hMYEmNG9/lib/python3.12/site-packages/django/utils/autoreload.py", line 64, in wrapper
    fn(*args, **kwargs)
  File "/home/paul/.local/share/virtualenvs/NeuroSys-AI-hMYEmNG9/lib/python3.12/site-packages/django/__init__.py", line 24, in setup
    apps.populate(settings.INSTALLED_APPS)
  File "/home/paul/.local/share/virtualenvs/NeuroSys-AI-hMYEmNG9/lib/python3.12/site-packages/django/apps/registry.py", line 116, in populate
    app_config.import_models()
  File "/home/paul/.local/share/virtualenvs/NeuroSys-AI-hMYEmNG9/lib/python3.12/site-packages/django/apps/config.py", line 269, in import_models
    self.models_module = import_module(models_module_name)
                         ^^^^^^^^^^^^^^^^^^^^^^^^^^^^^^^^^
  File "/usr/lib/python3.12/importlib/__init__.py", line 90, in import_module
    return _bootstrap._gcd_import(name[level:], package, level)
           ^^^^^^^^^^^^^^^^^^^^^^^^^^^^^^^^^^^^^^^^^^^^^^^^^^^^
  File "<frozen importlib._bootstrap>", line 1387, in _gcd_import
  File "<frozen importlib._bootstrap>", line 1360, in _find_and_load
  File "<frozen importlib._bootstrap>", line 1331, in _find_and_load_unlocked
  File "<frozen importlib._bootstrap>", line 935, in _load_unlocked
  File "<frozen importlib._bootstrap_external>", line 995, in exec_module
  File "<frozen importlib._bootstrap>", line 488, in _call_with_frames_removed
  File "/home/paul/.local/share/virtualenvs/NeuroSys-AI-hMYEmNG9/lib/python3.12/site-packages/django/contrib/auth/models.py", line 5, in <module>
    from django.contrib.auth.base_user import AbstractBaseUser, BaseUserManager
  File "/home/paul/.local/share/virtualenvs/NeuroSys-AI-hMYEmNG9/lib/python3.12/site-packages/django/contrib/auth/base_user.py", line 40, in <module>
    class AbstractBaseUser(models.Model):
  File "/home/paul/.local/share/virtualenvs/NeuroSys-AI-hMYEmNG9/lib/python3.12/site-packages/django/db/models/base.py", line 143, in __new__
    new_class.add_to_class("_meta", Options(meta, app_label))
  File "/home/paul/.local/share/virtualenvs/NeuroSys-AI-hMYEmNG9/lib/python3.12/site-packages/django/db/models/base.py", line 371, in add_to_class
    value.contribute_to_class(cls, name)
  File "/home/paul/.local/share/virtualenvs/NeuroSys-AI-hMYEmNG9/lib/python3.12/site-packages/django/db/models/options.py", line 231, in contribute_to_class
    self.db_table, connection.ops.max_name_length()
                   ^^^^^^^^^^^^^^
  File "/home/paul/.local/share/virtualenvs/NeuroSys-AI-hMYEmNG9/lib/python3.12/site-packages/django/utils/connection.py", line 15, in __getattr__
    return getattr(self._connections[self._alias], item)
                   ~~~~~~~~~~~~~~~~~^^^^^^^^^^^^^
  File "/home/paul/.local/share/virtualenvs/NeuroSys-AI-hMYEmNG9/lib/python3.12/site-packages/django/utils/connection.py", line 62, in __getitem__
    conn = self.create_connection(alias)
           ^^^^^^^^^^^^^^^^^^^^^^^^^^^^^
  File "/home/paul/.local/share/virtualenvs/NeuroSys-AI-hMYEmNG9/lib/python3.12/site-packages/django/db/utils.py", line 193, in create_connection
    backend = load_backend(db["ENGINE"])
              ^^^^^^^^^^^^^^^^^^^^^^^^^^
  File "/home/paul/.local/share/virtualenvs/NeuroSys-AI-hMYEmNG9/lib/python3.12/site-packages/django/db/utils.py", line 113, in load_backend
    return import_module("%s.base" % backend_name)
           ^^^^^^^^^^^^^^^^^^^^^^^^^^^^^^^^^^^^^^^
  File "/usr/lib/python3.12/importlib/__init__.py", line 90, in import_module
    return _bootstrap._gcd_import(name[level:], package, level)
           ^^^^^^^^^^^^^^^^^^^^^^^^^^^^^^^^^^^^^^^^^^^^^^^^^^^^
  File "/home/paul/.local/share/virtualenvs/NeuroSys-AI-hMYEmNG9/lib/python3.12/site-packages/django/db/backends/postgresql/base.py", line 29, in <module>
    raise ImproperlyConfigured("Error loading psycopg2 or psycopg module")
django.core.exceptions.ImproperlyConfigured: Error loading psycopg2 or psycopg module
Watching for file changes with StatReloader
Exception in thread django-main-thread:
Traceback (most recent call last):
  File "/home/paul/.local/share/virtualenvs/NeuroSys-AI-hMYEmNG9/lib/python3.12/site-packages/django/db/backends/postgresql/base.py", line 25, in <module>
    import psycopg as Database
ModuleNotFoundError: No module named 'psycopg'

During handling of the above exception, another exception occurred:

Traceback (most recent call last):
  File "/home/paul/.local/share/virtualenvs/NeuroSys-AI-hMYEmNG9/lib/python3.12/site-packages/django/db/backends/postgresql/base.py", line 27, in <module>
    import psycopg2 as Database
ModuleNotFoundError: No module named 'psycopg2'

During handling of the above exception, another exception occurred:

Traceback (most recent call last):
  File "/usr/lib/python3.12/threading.py", line 1073, in _bootstrap_inner
    self.run()
  File "/usr/lib/python3.12/threading.py", line 1010, in run
    self._target(*self._args, **self._kwargs)
  File "/home/paul/.local/share/virtualenvs/NeuroSys-AI-hMYEmNG9/lib/python3.12/site-packages/django/utils/autoreload.py", line 64, in wrapper
    fn(*args, **kwargs)
  File "/home/paul/.local/share/virtualenvs/NeuroSys-AI-hMYEmNG9/lib/python3.12/site-packages/django/core/management/commands/runserver.py", line 126, in inner_run
    autoreload.raise_last_exception()
  File "/home/paul/.local/share/virtualenvs/NeuroSys-AI-hMYEmNG9/lib/python3.12/site-packages/django/utils/autoreload.py", line 87, in raise_last_exception
    raise _exception[1]
  File "/home/paul/.local/share/virtualenvs/NeuroSys-AI-hMYEmNG9/lib/python3.12/site-packages/django/core/management/__init__.py", line 394, in execute
    autoreload.check_errors(django.setup)()
  File "/home/paul/.local/share/virtualenvs/NeuroSys-AI-hMYEmNG9/lib/python3.12/site-packages/django/utils/autoreload.py", line 64, in wrapper
    fn(*args, **kwargs)
  File "/home/paul/.local/share/virtualenvs/NeuroSys-AI-hMYEmNG9/lib/python3.12/site-packages/django/__init__.py", line 24, in setup
    apps.populate(settings.INSTALLED_APPS)
  File "/home/paul/.local/share/virtualenvs/NeuroSys-AI-hMYEmNG9/lib/python3.12/site-packages/django/apps/registry.py", line 116, in populate
    app_config.import_models()
  File "/home/paul/.local/share/virtualenvs/NeuroSys-AI-hMYEmNG9/lib/python3.12/site-packages/django/apps/config.py", line 269, in import_models
    self.models_module = import_module(models_module_name)
                         ^^^^^^^^^^^^^^^^^^^^^^^^^^^^^^^^^
  File "/usr/lib/python3.12/importlib/__init__.py", line 90, in import_module
    return _bootstrap._gcd_import(name[level:], package, level)
           ^^^^^^^^^^^^^^^^^^^^^^^^^^^^^^^^^^^^^^^^^^^^^^^^^^^^
  File "<frozen importlib._bootstrap>", line 1387, in _gcd_import
  File "<frozen importlib._bootstrap>", line 1360, in _find_and_load
  File "<frozen importlib._bootstrap>", line 1331, in _find_and_load_unlocked
  File "<frozen importlib._bootstrap>", line 935, in _load_unlocked
  File "<frozen importlib._bootstrap_external>", line 995, in exec_module
  File "<frozen importlib._bootstrap>", line 488, in _call_with_frames_removed
  File "/home/paul/.local/share/virtualenvs/NeuroSys-AI-hMYEmNG9/lib/python3.12/site-packages/django/contrib/auth/models.py", line 5, in <module>
    from django.contrib.auth.base_user import AbstractBaseUser, BaseUserManager
  File "/home/paul/.local/share/virtualenvs/NeuroSys-AI-hMYEmNG9/lib/python3.12/site-packages/django/contrib/auth/base_user.py", line 40, in <module>
    class AbstractBaseUser(models.Model):
  File "/home/paul/.local/share/virtualenvs/NeuroSys-AI-hMYEmNG9/lib/python3.12/site-packages/django/db/models/base.py", line 143, in __new__
    new_class.add_to_class("_meta", Options(meta, app_label))
  File "/home/paul/.local/share/virtualenvs/NeuroSys-AI-hMYEmNG9/lib/python3.12/site-packages/django/db/models/base.py", line 371, in add_to_class
    value.contribute_to_class(cls, name)
  File "/home/paul/.local/share/virtualenvs/NeuroSys-AI-hMYEmNG9/lib/python3.12/site-packages/django/db/models/options.py", line 231, in contribute_to_class
    self.db_table, connection.ops.max_name_length()
                   ^^^^^^^^^^^^^^
  File "/home/paul/.local/share/virtualenvs/NeuroSys-AI-hMYEmNG9/lib/python3.12/site-packages/django/utils/connection.py", line 15, in __getattr__
    return getattr(self._connections[self._alias], item)
                   ~~~~~~~~~~~~~~~~~^^^^^^^^^^^^^
  File "/home/paul/.local/share/virtualenvs/NeuroSys-AI-hMYEmNG9/lib/python3.12/site-packages/django/utils/connection.py", line 62, in __getitem__
    conn = self.create_connection(alias)
           ^^^^^^^^^^^^^^^^^^^^^^^^^^^^^
  File "/home/paul/.local/share/virtualenvs/NeuroSys-AI-hMYEmNG9/lib/python3.12/site-packages/django/db/utils.py", line 193, in create_connection
    backend = load_backend(db["ENGINE"])
              ^^^^^^^^^^^^^^^^^^^^^^^^^^
  File "/home/paul/.local/share/virtualenvs/NeuroSys-AI-hMYEmNG9/lib/python3.12/site-packages/django/db/utils.py", line 113, in load_backend
    return import_module("%s.base" % backend_name)
           ^^^^^^^^^^^^^^^^^^^^^^^^^^^^^^^^^^^^^^^
  File "/usr/lib/python3.12/importlib/__init__.py", line 90, in import_module
    return _bootstrap._gcd_import(name[level:], package, level)
           ^^^^^^^^^^^^^^^^^^^^^^^^^^^^^^^^^^^^^^^^^^^^^^^^^^^^
  File "/home/paul/.local/share/virtualenvs/NeuroSys-AI-hMYEmNG9/lib/python3.12/site-packages/django/db/backends/postgresql/base.py", line 29, in <module>
    raise ImproperlyConfigured("Error loading psycopg2 or psycopg module")
django.core.exceptions.ImproperlyConfigured: Error loading psycopg2 or psycopg module
